<?xml version="1.0" encoding="UTF-8"?>
<robot xmlns:xacro="http://www.ros.org/wiki/xacro">
  <xacro:macro name="main_link"
    params="tf_prefix parent name hardware p d initial_joint_position:=^|0.0">

    <xacro:include filename="$(find rbs_arm)/urdf/inc/joint_hardware.xacro" />
    <xacro:include filename="$(find rbs_arm)/urdf/inc/materials.xacro" />

    <joint name="${tf_prefix}${name}_joint" type="revolute">
      <limit lower="-2.43" upper="2.43" effort="78" velocity="0.52" />
      <!-- <origin rpy="0.0 0 -3.1416" xyz="0 0 0.11165"></origin> -->
      <origin rpy="0.0 0 0" xyz="0 0.0 0.15465"></origin>

      <parent link="${tf_prefix}${parent}" />
      <child link="${tf_prefix}${name}" />
      <axis xyz="1 0 0" />
    </joint>

    <link name="${tf_prefix}${name}">
      <inertial>
        <origin rpy="0 0 0" xyz="0.00027998 -0.045366 0.0068959"></origin>
        <mass value="0.42726"></mass>
        <inertia ixx="0.0013794" ixy="-4.0542E-05" ixz="-8.9181E-06" iyy="0.00047255"
          iyz="-3.4771E-05" izz="0.001587"></inertia>
      </inertial>
      <visual>
        <origin rpy="0 0 0" xyz="0 0 0"></origin>
        <geometry>
          <mesh filename="file://$(find rbs_arm)/meshes/visual/axis2_main.stl"></mesh>
        </geometry>
        <material name="">
          <color rgba="0.75294 0.75294 0.75294 1"></color>
        </material>
      </visual>
      <collision>
        <origin rpy="0 0 0" xyz="0 0 0"></origin>
        <geometry>
          <mesh filename="file://$(find rbs_arm)/meshes/collision/axis2_main.stl"></mesh>
        </geometry>
      </collision>
    </link>

    <xacro:joint_hardware joint_name="${tf_prefix}${name}_joint" hardware="${hardware}" p="${p}"
      d="${d}" initial_joint_position="${initial_joint_position}" />
    <!-- <xacro:rbs_materials link_name="${tf_prefix}${name}" link_type="main_link" /> -->

  </xacro:macro>
</robot>
