<?xml version="1.0" encoding="UTF-8"?>
<robot xmlns:xacro="http://www.ros.org/wiki/xacro">
  <xacro:macro name="ee_link" params="tf_prefix parent hardware p d initial_joint_position:=^|0.0">

    <xacro:include filename="$(find rbs_arm)/urdf/inc/joint_hardware.xacro" />
    <xacro:include filename="$(find rbs_arm)/urdf/inc/materials.xacro" />

    <joint name="${tf_prefix}ee_link_joint" type="revolute">
      <limit lower="-2.43" upper="2.43" effort="78" velocity="0.52" />
      <origin rpy="0 0 0.0" xyz="0.0 0.0 0.0754"></origin>
      <parent link="${tf_prefix}${parent}" />
      <child link="${tf_prefix}ee_link" />
      <axis xyz="0 0 1" />
    </joint>

    <joint name="${tf_prefix}tool0_joint" type="fixed">
      <origin rpy="0.00000 0.00000 0.00000" xyz="0.00000 0.00000 0.14100" />
      <parent link="${tf_prefix}ee_link" />
      <child link="${tf_prefix}tool0" />
    </joint>

    <link name="${tf_prefix}tool0" />

    <link name="${tf_prefix}ee_link">
      <inertial>
        <origin rpy="0 0 0" xyz="1.594E-06 0.085889 0.0021969"></origin>
        <mass value="0.20976"></mass>
        <inertia ixx="0.00016257" ixy="4.2628E-07" ixz="-3.8857E-07" iyy="0.00022468"
          iyz="2.1709E-05" izz="0.00023702"></inertia>
      </inertial>
      <visual>
        <origin rpy="0 0 0" xyz="0 0 0"></origin>
        <geometry>
          <mesh filename="file://$(find rbs_arm)/meshes/visual/axis7_tail.stl"></mesh>
        </geometry>
        <material name="">
          <color rgba="0.75294 0.75294 0.75294 1"></color>
        </material>
      </visual>
      <collision>
        <origin rpy="0 0 0" xyz="0 0 0"></origin>
        <geometry>
          <mesh filename="file://$(find rbs_arm)/meshes/collision/axis7_tail.stl"></mesh>
        </geometry>
      </collision>
    </link>

    <xacro:joint_hardware joint_name="${tf_prefix}ee_link_joint" hardware="${hardware}" p="${p}"
      d="${d}" initial_joint_position="${initial_joint_position}" />
    <!-- <xacro:rbs_materials link_name="${tf_prefix}ee_link" link_type="ee_link" /> -->

  </xacro:macro>
</robot>
