<?xml version="1.0"?>
<robot xmlns:xacro="http://www.ros.org/wiki/xacro">
  <xacro:include filename="$(find rbs_arm)/urdf/rbs_arm_ros2_control.xacro" />
  <xacro:include filename="$(find rbs_arm)/urdf/inc/materials.xacro" />

  <xacro:macro name="rbs_arm" params="tf_prefix *origin parent hardware">
    <!-- ros2_control description macros-->
    <xacro:rbs_arm_ros2_control name="rbs_arm_hardware_interface" tf_prefix="${tf_prefix}"
      hardware="${hardware}" />
    <!-- JOINTS-->
    <joint name="${tf_prefix}base_link_joint" type="fixed">
      <xacro:insert_block name="origin" />
      <parent link="${parent}" />
      <child link="${tf_prefix}base_link" />
    </joint>
    <joint name="${tf_prefix}ee_link_joint" type="revolute">
      <limit lower="-1.5708" upper="3.14159" effort="78" velocity="0.52" />
      <origin rpy="0.00000 0.00000 0.00000" xyz="0.10000 0.00000 0.09473" />
      <parent link="${tf_prefix}fork.003_link" />
      <child link="${tf_prefix}ee_link" />
      <axis xyz="0 1 0" />
    </joint>
    <joint name="${tf_prefix}fork002_link_joint" type="revolute">
      <limit lower="-3.14159" upper="3.14159" effort="78" velocity="0.52" />
      <origin rpy="0.00000 0.00000 0.00000" xyz="0.00000 0.00000 0.13300" />
      <parent link="${tf_prefix}main_link" />
      <child link="${tf_prefix}fork.002_link" />
      <axis xyz="0 0 1" />
    </joint>
    <joint name="${tf_prefix}fork003_link_joint" type="revolute">
      <limit lower="-3.14159" upper="3.14159" effort="78" velocity="0.52" />
      <origin rpy="0.00000 0.00000 0.00000" xyz="0.00000 0.00000 0.13300" />
      <parent link="${tf_prefix}main.001_link" />
      <child link="${tf_prefix}fork.003_link" />
      <axis xyz="0 0 1" />
    </joint>
    <joint name="${tf_prefix}fork001_link_joint" type="revolute">
      <limit lower="-3.14159" upper="3.14159" effort="78" velocity="0.52" />
      <origin rpy="0.00000 0.00000 -0.00000" xyz="0.00000 -0.00000 0.17833" />
      <parent link="${tf_prefix}base_link" />
      <child link="${tf_prefix}fork_link" />
      <axis xyz="0 0 1" />
    </joint>
    <joint name="${tf_prefix}main002_link_joint" type="revolute">
      <limit lower="-1.5708" upper="3.14159" effort="78" velocity="0.52" />
      <origin rpy="-0.00000 0.00000 0.00000" xyz="0.10000 0.00000 0.09400" />
      <parent link="${tf_prefix}fork.002_link" />
      <child link="${tf_prefix}main.001_link" />
      <axis xyz="0 1 0" />
    </joint>
    <joint name="${tf_prefix}main001_link_joint" type="revolute">
      <limit lower="-1.5708" upper="3.14159" effort="78" velocity="0.52" />
      <origin rpy="0.00000 0.00000 0.00000" xyz="0.10000 0.00000 0.09400" />
      <parent link="${tf_prefix}fork_link" />
      <child link="${tf_prefix}main_link" />
      <axis xyz="0 1 0" />
    </joint>
    <joint name="${tf_prefix}tool0_joint" type="fixed">
      <origin rpy="-0.00000 0.00000 -0.00000" xyz="0.00001 -0.00010 0.11000" />
      <parent link="${tf_prefix}ee_link" />
      <child link="${tf_prefix}tool0" />
    </joint>
    <!-- LINKS-->
    <link name="${tf_prefix}base_link">
      <collision name="${tf_prefix}base_collision">
        <origin rpy="0.00000 0.00000 0.00000" xyz="0.00000 0.00000 0.00000" />
        <geometry>
          <mesh filename="file://$(find rbs_arm)/meshes/collision/start_link.stl"
            scale="1.00000 1.00000 1.00000" />
        </geometry>
      </collision>
      <inertial>
        <inertia ixx="0.00503302470272442" ixy="0.000343817346410954" ixz="-4.74990755448368E-06"
          iyy="0.00337962410057753" iyz="-2.3099255620051E-05" izz="0.00405858207282473" />
        <origin rpy="0.00000 0.00000 0.00000"
          xyz="-0.000297002857922682 0.0964721185617698 -0.000361033370053684" />
        <mass value="1.88031044620482" />
      </inertial>
      <visual name="${tf_prefix}base_visual">
        <origin rpy="0.00000 0.00000 0.00000" xyz="0.00000 0.00000 0.00000" />
        <geometry>
          <mesh filename="file://$(find rbs_arm)/meshes/visual/start_link.dae"
            scale="1.00000 1.00000 1.00000" />
        </geometry>
      </visual>
    </link>
    <link name="${tf_prefix}ee_link">
      <collision name="${tf_prefix}ee_collision">
        <origin rpy="-0.00000 0.00000 -0.00000" xyz="0.00000 -0.00000 0.00000" />
        <geometry>
          <mesh filename="file://$(find rbs_arm)/meshes/collision/tail_link.stl"
            scale="1.00000 1.00000 1.00000" />
        </geometry>
      </collision>
      <inertial>
        <inertia ixx="0.00147695259043549" ixy="-2.66894744420299E-05" ixz="-4.40871314563273E-05"
          iyy="0.00135500487881796" iyz="-3.19001462979333E-05" izz="0.00087582892706912" />
        <origin rpy="0.00000 0.00000 0.00000"
          xyz="-9.7531539777207E-06 -0.000888494418875867 0.0342332199538358" />
        <mass value="1.88031044620482" />
      </inertial>
      <visual name="${tf_prefix}ee_visual">
        <origin rpy="0.00000 0.00000 0.00000" xyz="0.00000 -0.00000 0.00000" />
        <geometry>
          <mesh filename="file://$(find rbs_arm)/meshes/visual/tail_link.dae"
            scale="1.00000 1.00000 1.00000" />
        </geometry>
      </visual>
    </link>
    <link name="${tf_prefix}fork.002_link">
      <collision name="${tf_prefix}fork.002_collision">
        <origin rpy="0.00000 0.00000 0.00000" xyz="0.00000 -0.00000 0.00000" />
        <geometry>
          <mesh filename="file://$(find rbs_arm)/meshes/collision/fork.stl"
            scale="1.00000 1.00000 1.00000" />
        </geometry>
      </collision>
      <inertial>
        <inertia ixx="0.00367804533572758" ixy="1.04277925521833E-05" ixz="-0.00149971410403071"
          iyy="0.00415208849477534" iyz="-0.00122" izz="0.00329" />
        <origin rpy="0.00000 0.00000 0.00000"
          xyz="0.0472051139085306 0.00208890925682996 0.0557265410642575" />
        <mass value="1.12472202892859" />
      </inertial>
      <visual name="${tf_prefix}fork.002_visual">
        <origin rpy="0.00000 -0.00000 -0.00000" xyz="0.00000 -0.00000 0.00000" />
        <geometry>
          <mesh filename="file://$(find rbs_arm)/meshes/visual/fork.dae"
            scale="1.00000 1.00000 1.00000" />
        </geometry>
      </visual>
    </link>
    <link name="${tf_prefix}fork.003_link">
      <collision name="${tf_prefix}fork.003_collision">
        <origin rpy="-0.00000 0.00000 0.00000" xyz="0.00000 -0.00000 0.00000" />
        <geometry>
          <mesh filename="file://$(find rbs_arm)/meshes/collision/fork.stl"
            scale="1.00000 1.00000 1.00000" />
        </geometry>
      </collision>
      <inertial>
        <inertia ixx="0.00367804533572758" ixy="1.04277925521833E-05" ixz="-0.00149971410403071"
          iyy="0.00415208849477534" iyz="-0.00122" izz="0.00329" />
        <origin rpy="0.00000 0.00000 0.00000"
          xyz="0.0472051139085306 0.00208890925682996 0.0557265410642575" />
        <mass value="1.12472202892859" />
      </inertial>
      <visual name="${tf_prefix}fork.003_visual">
        <origin rpy="-0.00000 0.00000 -0.00000" xyz="0.00000 -0.00000 0.00000" />
        <geometry>
          <mesh filename="file://$(find rbs_arm)/meshes/visual/fork.dae"
            scale="1.00000 1.00000 1.00000" />
        </geometry>
      </visual>
    </link>
    <link name="${tf_prefix}fork_link">
      <collision name="${tf_prefix}fork_collision">
        <origin rpy="0.00000 0.00000 0.00000" xyz="-0.00000 0.00000 0.00000" />
        <geometry>
          <mesh filename="file://$(find rbs_arm)/meshes/collision/fork.stl"
            scale="1.00000 1.00000 1.00000" />
        </geometry>
      </collision>
      <inertial>
        <inertia ixx="0.00367804533572758" ixy="1.04277925521833E-05" ixz="-0.00149971410403071"
          iyy="0.00415208849477534" iyz="-0.00122" izz="0.00329" />
        <origin rpy="0.00000 0.00000 0.00000"
          xyz="0.0472051139085306 0.00208890925682996 0.0557265410642575" />
        <mass value="1.12472202892859" />
      </inertial>
      <visual name="${tf_prefix}fork_visual">
        <origin rpy="0.00000 0.00000 -0.00000" xyz="-0.00000 0.00000 0.00000" />
        <geometry>
          <mesh filename="file://$(find rbs_arm)/meshes/visual/fork.dae"
            scale="1.00000 1.00000 1.00000" />
        </geometry>
      </visual>
    </link>
    <link name="${tf_prefix}main.001_link">
      <collision name="${tf_prefix}main.001_collision">
        <origin rpy="0.00000 0.00000 0.00000" xyz="0.00000 0.00000 0.00000" />
        <geometry>
          <mesh filename="file://$(find rbs_arm)/meshes/collision/main_link.stl"
            scale="1.00000 1.00000 1.00000" />
        </geometry>
      </collision>
      <inertial>
        <inertia ixx="0.00315699373090845" ixy="2.84713820858537E-05" ixz="-7.01601261191721E-05"
          iyy="0.00343729241263707" iyz="-0.000101485203138902" izz="0.00125534890134052" />
        <origin rpy="0.00000 0.00000 0.00000"
          xyz="0.00186712264682627 -0.000412152188777604 0.0516389446895805" />
        <mass value="1.58688811563124" />
      </inertial>
      <visual name="${tf_prefix}main.001_visual">
        <origin rpy="0.00000 -0.00000 -0.00000" xyz="0.00000 0.00000 0.00000" />
        <geometry>
          <mesh filename="file://$(find rbs_arm)/meshes/visual/main_link.dae"
            scale="1.00000 1.00000 1.00000" />
        </geometry>
      </visual>
    </link>
    <link name="${tf_prefix}main_link">
      <collision name="${tf_prefix}main_collision">
        <origin rpy="0.00000 0.00000 0.00000" xyz="0.00000 0.00000 0.00000" />
        <geometry>
          <mesh filename="file://$(find rbs_arm)/meshes/collision/main_link.stl"
            scale="1.00000 1.00000 1.00000" />
        </geometry>
      </collision>
      <inertial>
        <inertia ixx="0.00315699373090845" ixy="2.84713820858537E-05" ixz="-7.01601261191721E-05"
          iyy="0.00343729241263707" iyz="-0.000101485203138902" izz="0.00125534890134052" />
        <origin rpy="0.00000 0.00000 0.00000"
          xyz="0.00186712264682627 -0.000412152188777604 0.0516389446895805" />
        <mass value="1.58688811563124" />
      </inertial>
      <visual name="${tf_prefix}main_visual">
        <origin rpy="0.00000 -0.00000 -0.00000" xyz="0.00000 0.00000 0.00000" />
        <geometry>
          <mesh filename="file://$(find rbs_arm)/meshes/visual/main_link.dae"
            scale="1.00000 1.00000 1.00000" />
        </geometry>
      </visual>
    </link>
    <link name="${tf_prefix}tool0" />
    <!-- MATERIALS-->
    <xacro:rbs_materials link_name="${tf_prefix}main_link" link_type="main_link" />
  </xacro:macro>
</robot>
